ValueError: This app has encountered an error. The original error message is redacted to prevent data leaks. Full error details have been recorded in the logs (if you're on Streamlit Cloud, click on 'Manage app' in the lower right of your app).
Traceback:
File "/home/adminuser/venv/lib/python3.11/site-packages/streamlit/runtime/scriptrunner/script_runner.py", line 589, in _run_script
    exec(code, module.__dict__)
File "/mount/src/stock-predic/app.py", line 239, in <module>
    latest_feat = scaler.transform(proc[imp.index].iloc[[-1]])
                  ^^^^^^^^^^^^^^^^^^^^^^^^^^^^^^^^^^^^^^^^^^^^
File "/home/adminuser/venv/lib/python3.11/site-packages/sklearn/utils/_set_output.py", line 295, in wrapped
    data_to_wrap = f(self, X, *args, **kwargs)
                   ^^^^^^^^^^^^^^^^^^^^^^^^^^^
File "/home/adminuser/venv/lib/python3.11/site-packages/sklearn/preprocessing/_data.py", line 1043, in transform
    X = self._validate_data(
        ^^^^^^^^^^^^^^^^^^^^
File "/home/adminuser/venv/lib/python3.11/site-packages/sklearn/base.py", line 608, in _validate_data
    self._check_feature_names(X, reset=reset)
File "/home/adminuser/venv/lib/python3.11/site-packages/sklearn/base.py", line 535, in _check_feature_names
    raise ValueError(message)
